Workbook

Sheet Dane
B2: KALKULATOR NK38 - DANE WEJŚCIOWE
B3: Wypełniasz tylko żółte pola. Puste pole = 0 lub wartość automatyczna. Wynik: arkusz Podsumowanie.
B5: 1. Inwestycja
B6: Nazwa / adres inwestycji | C6: ul. ...
B7: Data oferty
B8: Nr oferty / handlowiec | C8: SNK
B9: Opis / wariant (H, L, P, Hpoj ...)
B11: 2. Lokalizacja
B12: Lokalizacja | C12: Poza Krakowem | E12: Kraków: montaż w dniach, 20 km, bez hotelu i diet
B13: Odległość od Krakowa [km, faktyczna, w jedną stronę] | C13: 0 | E13: Pomiary = ta odległość, montaż = +50 km
B14: Nadpisz: km na pomiary / odbiory | E14: puste = automatycznie
B15: Nadpisz: km na montaż | E15: puste = automatycznie
B17: 3. Urządzenia
B18: Typ urządzenia | C18: NK38
B19: Platformy pojedyncze S (2 MP) | C19: 0
B20: Platformy podwójne D (4 MP) | C20: 0
B21: Systemy dla N.P. (2 MP, liczone jak D) | C21: 0
B22: Agregaty | C22: 0 | E22: Zależy od układu garażu (1 agregat do 6 platform)
B23: Magistrala EXTRA [odcinki 6 m] | C23: 0
B24: Barierki [szt. na stronę] | C24: 0
B25: Maskownice / bariery tylne | C25: 0
B26: Utrudnienia - dodatkowe osobodni (ręcznie) | C26: 0 | E26: Doliczane do utrudnień z magistrali i barierek (dawny 'tonaż')
B28: 4. Wymiary niestandardowe (ile platform danego typu)
C29: S | D29: D | E29: Pozostałe platformy = wymiar standardowy (250/500, 170, 530) | F29: (pomocnicze do opisu)
B30: Zagłębienie 175 cm | C30: 0 | D30: 0 | F30: =IF(C30+D30>0,"; 175 cm: "&IF(C30>0,C30&"S","")&IF(AND(C30>0,D30>0),"+","")&IF(D30>0,D30&"D",""),"")
B31: Zagłębienie 180 cm | C31: 0 | D31: 0 | F31: =IF(C31+D31>0,"; 180 cm: "&IF(C31>0,C31&"S","")&IF(AND(C31>0,D31>0),"+","")&IF(D31>0,D31&"D",""),"")
B32: Zagłębienie 185 cm | C32: 0 | D32: 0 | F32: =IF(C32+D32>0,"; 185 cm: "&IF(C32>0,C32&"S","")&IF(AND(C32>0,D32>0),"+","")&IF(D32>0,D32&"D",""),"")
B33: Zagłębienie 190 cm | C33: 0 | D33: 0 | F33: =IF(C33+D33>0,"; 190 cm: "&IF(C33>0,C33&"S","")&IF(AND(C33>0,D33>0),"+","")&IF(D33>0,D33&"D",""),"")
B34: Zagłębienie 195 cm | C34: 0 | D34: 0 | F34: =IF(C34+D34>0,"; 195 cm: "&IF(C34>0,C34&"S","")&IF(AND(C34>0,D34>0),"+","")&IF(D34>0,D34&"D",""),"")
B35: Zagłębienie 200 cm | C35: 0 | D35: 0 | F35: =IF(C35+D35>0,"; 200 cm: "&IF(C35>0,C35&"S","")&IF(AND(C35>0,D35>0),"+","")&IF(D35>0,D35&"D",""),"")
B36: Zagłębienie 210 cm | C36: 0 | D36: 0 | F36: =IF(C36+D36>0,"; 210 cm: "&IF(C36>0,C36&"S","")&IF(AND(C36>0,D36>0),"+","")&IF(D36>0,D36&"D",""),"")
B37: Zagłębienie 220 cm | C37: 0 | D37: 0 | F37: =IF(C37+D37>0,"; 220 cm: "&IF(C37>0,C37&"S","")&IF(AND(C37>0,D37>0),"+","")&IF(D37>0,D37&"D",""),"")
B38: Zagłębienie 225 cm | C38: 0 | D38: 0 | F38: =IF(C38+D38>0,"; 225 cm: "&IF(C38>0,C38&"S","")&IF(AND(C38>0,D38>0),"+","")&IF(D38>0,D38&"D",""),"")
B39: Zagłębienie 170 cm (standard) - wyliczone | C39: =in_S-SUM(in_gl_S) -> 0 | D39: =in_D-SUM(in_gl_D) -> 0
B40: Szerokość 260 (S) / 520 (D) | C40: 0 | D40: 0 | F40: =IF(C40+D40>0,"; szer. 260 (S) / 520 (D): "&IF(C40>0,C40&"S","")&IF(AND(C40>0,D40>0),"+","")&IF(D40>0,D40&"D",""),"")
B41: Szerokość 270 (S) / 540 (D) | C41: 0 | D41: 0 | F41: =IF(C41+D41>0,"; szer. 270 (S) / 540 (D): "&IF(C41>0,C41&"S","")&IF(AND(C41>0,D41>0),"+","")&IF(D41>0,D41&"D",""),"")
B42: Długość zagłębienia 500-510 cm | C42: 0 | D42: 0 | F42: =IF(C42+D42>0,"; dł. 500-510 cm: "&IF(C42>0,C42&"S","")&IF(AND(C42>0,D42>0),"+","")&IF(D42>0,D42&"D",""),"")
B43: Długość zagłębienia 540 cm | C43: 0 | D43: 0 | F43: =IF(C43+D43>0,"; dł. 540 cm: "&IF(C43>0,C43&"S","")&IF(AND(C43>0,D43>0),"+","")&IF(D43>0,D43&"D",""),"")
B44: Długość zagłębienia 550 cm | C44: 0 | D44: 0 | F44: =IF(C44+D44>0,"; dł. 550 cm: "&IF(C44>0,C44&"S","")&IF(AND(C44>0,D44>0),"+","")&IF(D44>0,D44&"D",""),"")
F45: =MID(F30&F31&F32&F33&F34&F35&F36&F37&F38,3,500)
...

Sheet Podsumowanie
B2: PODSUMOWANIE OFERTY NK38
B3: =in_nazwa&" | "&IF(ISBLANK(in_data),"",TEXT(in_data,"yyyy-mm-dd"))&" | "&in_nr -> ul. ... | | SNK
B4: =in_typ&" "&IF(in_S>0,in_S&"S250","")&IF(AND(in_S>0,in_D>0),"+","")&IF(in_D>0,in_D&"D500","")&IF(in_NP>0,"+"&in_NP&"NP","")&", "&in_agregaty&"A | "&m_MP&" MP | "&in_lok -> NK38 , 0A | 0 MP | Poza Krakowem
B6: Wariant | C6: 2000 kg | D6: 2500 kg | E6: 2000 kg + słupki | F6: 2500 kg + słupki
B7: CENA KONTRAKTU NETTO | C7: =Obliczenia!D70 -> 1813.142 | D7: =Obliczenia!E70 -> 1813.142 | E7: =Obliczenia!F70 -> 1813.142 | F7: =Obliczenia!G70 -> 1813.142
B8: Cena za miejsce postojowe | C8: =Obliczenia!D72 -> 0 | D8: =Obliczenia!E72 -> 0 | E8: =Obliczenia!F72 -> 0 | F8: =Obliczenia!G72 -> 0
B9: Cena za MP [EUR] | C9: =Obliczenia!D73 -> 0 | D9: =Obliczenia!E73 -> 0 | E9: =Obliczenia!F73 -> 0 | F9: =Obliczenia!G73 -> 0
B10: Cena minimalna (zysk do sprawdzenia) | C10: =Obliczenia!D75 -> 1756.4017 | D10: =Obliczenia!E75 -> 1756.4017 | E10: =Obliczenia!F75 -> 1756.4017 | F10: =Obliczenia!G75 -> 1756.4017
B11: Zysk | C11: =Obliczenia!D68 -> 216.64201 | D11: =Obliczenia!E68 -> 216.64201 | E11: =Obliczenia!F68 -> 216.64201 | F11: =Obliczenia!G68 -> 216.64201
B12: Koszt rzeczywisty | C12: =Obliczenia!D71 -> 1596.4999 | D12: =Obliczenia!E71 -> 1596.4999 | E12: =Obliczenia!F71 -> 1596.4999 | F12: =Obliczenia!G71 -> 1596.4999
B14: Urządzenia (materiały) | C14: =Obliczenia!D53 -> 0 | D14: =Obliczenia!E53 -> 0 | E14: =Obliczenia!F53 -> 0 | F14: =Obliczenia!G53 -> 0
B15: Słupki e-ładowarek | C15: =Obliczenia!D54 -> 0 | D15: =Obliczenia!E54 -> 0 | E15: =Obliczenia!F54 -> 0 | F15: =Obliczenia!G54 -> 0
B16: Transport, dźwig, rozładunek | C16: =Obliczenia!D57+Obliczenia!D58+Obliczenia!D59 -> 0 | D16: =Obliczenia!E57+Obliczenia!E58+Obliczenia!E59 -> 0 | E16: =Obliczenia!F57+Obliczenia!F58+Obliczenia!F59 -> 0 | F16: =Obliczenia!G57+Obliczenia!G58+Obliczenia!G59 -> 0
B17: Robocizna (montaż, rozładunek, dojazdy) | C17: =Obliczenia!D62+Obliczenia!D60+Obliczenia!D61 -> 280 | D17: =Obliczenia!E62+Obliczenia!E60+Obliczenia!E61 -> 280 | E17: =Obliczenia!F62+Obliczenia!F60+Obliczenia!F61 -> 280 | F17: =Obliczenia!G62+Obliczenia!G60+Obliczenia!G61 -> 280
B18: Hotel, diety, paliwo | C18: =Obliczenia!D56+Obliczenia!D63+Obliczenia!D55 -> 1184.5 | D18: =Obliczenia!E56+Obliczenia!E63+Obliczenia!E55 -> 1184.5 | E18: =Obliczenia!F56+Obliczenia!F63+Obliczenia!F55 -> 1184.5 | F18: =Obliczenia!G56+Obliczenia!G63+Obliczenia!G55 -> 1184.5
B19: KOB + GDW + podatek | C19: =Obliczenia!D66+Obliczenia!D67+Obliczenia!D69 -> 131.99994 | D19: =Obliczenia!E66+Obliczenia!E67+Obliczenia!E69 -> 131.99994 | E19: =Obliczenia!F66+Obliczenia!F67+Obliczenia!F69 -> 131.99994 | F19: =Obliczenia!G66+Obliczenia!G67+Obliczenia!G69 -> 131.99994
B21: Dni pracy ekipy | C21: =Obliczenia!D51 -> 1 | D21: =Obliczenia!E51 -> 1 | E21: =Obliczenia!F51 -> 1 | F21: =Obliczenia!G51 -> 1
B22: Tygodnie (Kraków: dni) montażu | C22: =Obliczenia!D48 -> 1 | D22: =Obliczenia!E48 -> 1 | E22: =Obliczenia!F48 -> 1 | F22: =Obliczenia!G48 -> 1
B23: Osobodni razem | C23: =Obliczenia!D50 -> 0.7 | D23: =Obliczenia!E50 -> 0.7 | E23: =Obliczenia!F50 -> 0.7 | F23: =Obliczenia!G50 -> 0.7
B25: Opcje do oferty (cena z narzutami) | C25: Q=2000 kg | D25: Q=2500 kg
B26: Słupki e-ładowarek 3,7 kW (z robocizną) | C26: =Obliczenia!F70-Obliczenia!D70 -> 0 | D26: =Obliczenia!G70-Obliczenia!E70 -> 0
B27: Słupki e-ładowarek 22 kW (z robocizną) | C27: =Obliczenia!F70-Obliczenia!D70+(c_slupek22-c_slupek)*m_MP*e_mnoznik -> 0 | D27: =Obliczenia!G70-Obliczenia!E70+(c_slupek22-c_slupek)*m_MP*e_mnoznik -> 0
B28: Malowanie proszkowe RAL | C28: =m_malowanie*e_mnoznik -> 0 | D28: =m_malowanie*e_mnoznik -> 0
B30: ="Analiza liczby osób - wariant: "&in_analiza -> Analiza liczby osób - wariant: 2000 kg
B31: Liczba osób | C31: 2 os. | D31: 3 os. | E31: 4 os. | F31: 5 os. | G31: 6 os. | H31: 7 os.
B32: Cena kontraktu | C32: =Obliczenia!I70 -> 998.43399 | D32: =Obliczenia!J70 -> 1405.788 | E32: =Obliczenia!K70 -> 1813.142 | F32: =Obliczenia!L70 -> 2220.4959 | G32: =Obliczenia!M70 -> 2627.8499 | H32: =Obliczenia!N70 -> 3035.2039
B33: Cena za MP | C33: =Obliczenia!I72 -> 0 | D33: =Obliczenia!J72 -> 0 | E33: =Obliczenia!K72 -> 0 | F33: =Obliczenia!L72 -> 0 | G33: =Obliczenia!M72 -> 0 | H33: =Obliczenia!N72 -> 0
B34: Dni pracy ekipy | C34: =Obliczenia!I51 -> 1 | D34: =Obliczenia!J51 -> 1 | E34: =Obliczenia!K51 -> 1 | F34: =Obliczenia!L51 -> 1 | G34: =Obliczenia!M51 -> 1 | H34: =Obliczenia!N51 -> 1
B35: Tygodnie (Kraków: dni) | C35: =Obliczenia!I48 -> 1 | D35: =Obliczenia!J48 -> 1 | E35: =Obliczenia!K48 -> 1 | F35: =Obliczenia!L48 -> 1 | G35: =Obliczenia!M48 -> 1 | H35: =Obliczenia!N48 -> 1
B36: Hotel + diety | C36: =Obliczenia!I56+Obliczenia!I63 -> 535.75 | D36: =Obliczenia!J56+Obliczenia!J63 -> 803.625 | E36: =Obliczenia!K56+Obliczenia!K63 -> 1071.5 | F36: =Obliczenia!L56+Obliczenia!L63 -> 1339.375 | G36: =Obliczenia!M56+Obliczenia!M63 -> 1607.25 | H36: =Obliczenia!N56+Obliczenia!N63 -> 1875.125
B37: Zielone = najtańsza liczba osób
B39: Zestawienie do oferty
B40: Urządzenia | C40: =in_typ&": "&IF(in_S>0,in_S&" x S (2 MP) ","")&IF(in_D>0,in_D&" x D (4 MP) ","")&IF(in_NP>0,in_NP&" x N.P. ","")&"= "&m_MP&" MP" -> NK38: = 0 MP
B41: Agregaty | C41: =in_agregaty&" szt." -> 0 szt.
B42: Zagłębienia niestandardowe | C42: =IF(t_zaglebienia="","standard 170 cm",t_zaglebienia) -> standard 170 cm
B43: Wymiary niestandardowe | C43: =IF(t_wymiary="","standard",t_wymiary) -> standard
B44: Magistrala EXTRA / barierki / maskownice | C44: =in_magistrala&" x 6 m / "&in_barierki&" szt. / "&in_maskownice&" szt." -> 0 x 6 m / 0 szt. / 0 szt.
B45: Utrudnienia [osobodni] | C45: =m_utr&" (z magistrali i barierek "&m_utr_auto&", ręcznie "&in_utr_dod&")" -> 0 (z magistrali i barierek 0, ręcznie 0)
B46: Lokalizacja | C46: =in_lok&IF(e_krk,""," ("&in_km&" km od Krakowa)") -> Poza Krakowem (0 km od Krakowa)
B47: Km pomiary / montaż | C47: =e_km_pom&" / "&e_km_mon&" km" -> 0 / 50 km
...

Sheet Cennik
B2: CENNIK I STAŁE KALKULACYJNE NK38
B3: Zmiana ceny tutaj działa we wszystkich formułach. Kolumna E = skąd wartość pochodzi w starym arkuszu.
B5: Platformy
B6: Platforma podwójna NK38-500-170-530 (4 MP) | C6: 32500 | E6: NK38!E32
B7: Dopłata za NK37 / system | C7: 700 | E7: NK38!F1
B8: Cena S jako ułamek ceny D | C8: 0.61 | E8: NK38!F3
B9: Cena systemu N.P. jako ułamek ceny D | C9: 0.85 | E9: NK38!E27
B10: Szerokość S 260 cm | C10: 1170 | E10: NK38!E8
B11: Szerokość S 270 cm | C11: 1560 | E11: NK38!E9
B12: Szerokość D 520 cm | C12: 1820 | E12: NK38!E34
B13: Szerokość D 540 cm | C13: 3110 | E13: NK38!E35
B14: Długość zagłębienia 500-510 cm | C14: 2340 | E14: NK38!E21/E47
B15: Dopłata za 1 cm długości (ułamek ceny platformy) | C15: 0.00127 | E15: NK38!E22 (4 kg/cm z 3150 kg)
B16: Dopłata Q=2500 kg (domyślna) | C16: 0.07 | E16: NK38!D90
B17: Hydraulika
B18: Agregat 11,5 l/min (do 6 platform) | C18: 6500 | E18: NK38!E56
B19: Olej 150 l / agregat | C19: 1500 | E19: NK38!D134
B20: Elementy drobne / agregat | C20: 200 | E20: NK38!D135
B21: Transport agregatu | C21: 500 | E21: NK38!F57
B22: Transport siłowników / platformę | C22: 50 | E22: NK38!F57
B23: Siłownik standard (zagł. 170) | C23: 1080 | E23: NK38!D130
B24: Siłownik do zagł. 2000 (też 175 cm) | C24: 1175 | E24: NK38!D129
B25: Siłownik do zagł. 2250 | C25: 1250 | E25: NK38!D128
B26: Magistrala EXTRA / 6 m | C26: =0.2*11+0.4*11+2*14+6*11+6*5+6*10 -> 190.6 | E26: NK38!D133
B27: Barierki, elektryka, administracja
B28: Barierka na stronę (Metazet 538 zł) | C28: 600 | E28: NK38!E66
B29: Maskownica / bariera tylna (Metazet 608 zł) | C29: 700 | E29: NK38!E67
B30: Elektryka - skrzynka zasilająca / agregat | C30: 1000 | E30: NK38!D121
B31: Administracja, koszty biura / agregat | C31: 1800 | E31: NK38!D125
B32: Opcje oferty
B33: Malowanie proszkowe RAL - system S | C33: 6400 | E33: NK38!E92
B34: Malowanie proszkowe RAL - system D / NP | C34: 13500 | E34: NK38!E93
B35: Malowanie barierki na stronę | C35: 200 | E35: NK38!E94
B36: Słupek e-ładowarki do 3,7 kW / MP | C36: 1700 | E36: NK38!E97, KAL!O55
B37: Słupek e-ładowarki do 22 kW / MP | C37: 6300 | E37: NK38!E98
B38: Robocizna słupka (roboczodni / MP) | C38: 0.37 | E38: KAL!B49
B39: Montaż - pracochłonność
B40: Osobodni montażu / system S | C40: 5.5 | E40: KAL!F16
B41: Osobodni montażu / system D | C41: 7 | E41: KAL!F16
B42: Osobodni montażu / system NP | C42: 7 | E42: KAL!F17
...

Sheet Obliczenia
B2: OBLICZENIA (nie edytować)
B4: A. Materiały i urządzenia (dawny arkusz 'NK38 ...')
B5: Cena platformy D | C5: =c_cena_D+IF(in_typ="NK37",c_doplata_NK37,0) -> 32500
B6: Cena platformy S | C6: =c_wsp_S*m_cena_D -> 19825
B7: Cena systemu N.P. | C7: =c_wsp_NP*m_cena_D -> 27625
B8: Platformy D + N.P. (N.P. jak D) | C8: =in_D+in_NP -> 0
B9: Razem platform | C9: =in_S+in_D+in_NP -> 0
B10: Miejsca postojowe | C10: =2*in_S+2*in_NP+4*in_D -> 0
B11: Platformy S z dopłatami | C11: =m_cena_S*in_S+c_szer_260*in_szer1_S+c_szer_270*in_szer2_S+SUMPRODUCT(in_gl_S,t_gl_doplata)+c_dl_500*in_dl500_S+CEILING(m_cena_S*c_dl_wsp*10,100)*in_dl540_S+CEILING(m_cena_S*c_dl_wsp*20,100)*in_dl550_S -> 0
B12: Platformy D z dopłatami | C12: =m_cena_D*in_D+c_szer_520*in_szer1_D+c_szer_540*in_szer2_D+SUMPRODUCT(in_gl_D,t_gl_doplata)+c_dl_500*in_dl500_D+m_cena_D*c_dl_wsp*10*in_dl540_D+m_cena_D*c_dl_wsp*20*in_dl550_D -> 0
B13: Platformy N.P. | C13: =m_cena_NP*in_NP -> 0
B14: Siłowniki 2000 [pary] | C14: =SUMPRODUCT((t_gl_silownik=2000)*(in_gl_S+in_gl_D)) -> 0
B15: Siłowniki 2250 [pary] | C15: =SUMPRODUCT((t_gl_silownik=2250)*(in_gl_S+in_gl_D)) -> 0
B16: Siłowniki standard [pary] (z N.P.) | C16: =m_platformy-m_sil_2000-m_sil_2250 -> 0
B17: Hydraulika | C17: =in_agregaty*(c_agregat+c_hydr_drobne+c_olej+c_transp_agregatu)+m_platformy*c_transp_silownikow+2*(c_sil_1700*m_sil_std+c_sil_2000*m_sil_2000+c_sil_2250*m_sil_2250)+in_magistrala*c_magistrala+SUMPRODUCT((t_sk_grupa="Hydraulika")*t_sk_cena*(t_sk_S*in_S+t_sk_D*m_DN)) -> 0
B18: Barierki i maskownice | C18: =in_barierki*c_barierka+in_maskownice*c_maskownica -> 0
B19: Elektryka | C19: =in_agregaty*c_skrzynka_zasil+SUMPRODUCT((t_sk_grupa="Elektryka")*t_sk_cena*(t_sk_S*in_S+t_sk_D*m_DN)) -> 0
B20: Mechanika zakupowa i pozostałe | C20: =in_agregaty*c_admin+SUMPRODUCT((t_sk_grupa="Mechanika")*t_sk_cena*(t_sk_S*in_S+t_sk_D*m_DN)) -> 0
B21: SUMA STANDARD Q=2000 (dawne F87) | C21: =m_plat_S+m_plat_D+m_plat_NP+m_hydraulika+m_barierki+m_elektryka+m_mechanika -> 0
B22: SUMA Q=2500 (dawne F90) | C22: =m_suma_2000*(1+in_q2500) -> 0
B23: Opcja: malowanie proszkowe RAL (koszt) | C23: =c_mal_S*in_S+c_mal_D*m_DN+c_mal_bar*in_barierki -> 0
B24: Utrudnienia z magistrali i barierek [osobodni] | C24: =ROUNDUP(in_magistrala*c_osd_magistrala+(in_barierki+in_maskownice)*c_osd_barierka,0) -> 0
B25: Utrudnienia razem [osobodni] (dawny 'tonaż') | C25: =m_utr_auto+in_utr_dod -> 0
B27: B. Parametry montażu wspólne dla wariantów
B28: Kraków? | C28: =in_lok="Kraków" -> FALSE
B29: Km na pomiary / odbiory | C29: =IF(ISBLANK(in_km_pom),IF(e_krk,c_km_krakow,in_km),in_km_pom) -> 0
B30: Km na montaż | C30: =IF(ISBLANK(in_km_mon),IF(e_krk,c_km_krakow,in_km+c_km_dodatek),in_km_mon) -> 50
B31: Dni rozładunku | C31: =IF(ISBLANK(in_rozl_dni),c_rozl_TIR*in_tir,in_rozl_dni) -> 0
B32: Podróże pomiary + odbiory [osobodni] | C32: =(c_pomiary_osoby+c_odbiory_osoby)*IF(in_wzor="Uproszczony",2*e_km_pom/c_km_dzien*1,(1+0.1*MAX(0,800-e_km_pom)/100)*e_km_pom*1/500) -> 0
B33: Dni dźwigu | C33: =ROUNDUP(m_DN/c_dzwig_D+in_S*c_dzwig_wspS/c_dzwig_D,0) -> 0
B34: Mnożnik kosztu materiałowego na cenę (opcje) | C34: =(1+c_podatek*(c_gdw+in_zysk))/(1-(c_kob+c_gdw+in_zysk)) -> 1.208284
B36: C. Montaż i cena (dawny arkusz '<Inwestycja>-NK38') | I36: Analiza liczby osób (wariant z Dane)
B37: Wariant / liczba osób | D37: 2000 kg | E37: 2500 kg | F37: 2000 kg + słupki | G37: 2500 kg + słupki | I37: 2 os. | J37: 3 os. | K37: 4 os. | L37: 5 os. | M37: 6 os. | N37: 7 os.
B38: Q=2500? (1/0) | D38: 0 | E38: 1 | F38: 0 | G38: 1 | I38: =IF(LEFT(in_analiza,4)="2500",1,0) -> 0 | J38: =IF(LEFT(in_analiza,4)="2500",1,0) -> 0 | K38: =IF(LEFT(in_analiza,4)="2500",1,0) -> 0 | L38: =IF(LEFT(in_analiza,4)="2500",1,0) -> 0 | M38: =IF(LEFT(in_analiza,4)="2500",1,0) -> 0 | N38: =IF(LEFT(in_analiza,4)="2500",1,0) -> 0
B39: Słupki e-ładowarek? (1/0) | D39: 0 | E39: 0 | F39: 1 | G39: 1 | I39: =IF(ISNUMBER(SEARCH("słupki",in_analiza)),1,0) -> 0 | J39: =IF(ISNUMBER(SEARCH("słupki",in_analiza)),1,0) -> 0 | K39: =IF(ISNUMBER(SEARCH("słupki",in_analiza)),1,0) -> 0 | L39: =IF(ISNUMBER(SEARCH("słupki",in_analiza)),1,0) -> 0 | M39: =IF(ISNUMBER(SEARCH("słupki",in_analiza)),1,0) -> 0 | N39: =IF(ISNUMBER(SEARCH("słupki",in_analiza)),1,0) -> 0
B40: Liczba osób | D40: =in_osoby -> 4 | E40: =in_osoby -> 4 | F40: =in_osoby -> 4 | G40: =in_osoby -> 4 | I40: 2 | J40: 3 | K40: 4 | L40: 5 | M40: 6 | N40: 7
B41: Średnia stawka dzienna | D41: =(c_stawka_1+IF(D40>=2,c_stawka_2,0)+MAX(0,D40-2)*c_stawka_n)/D40 -> 400 | E41: =(c_stawka_1+IF(E40>=2,c_stawka_2,0)+MAX(0,E40-2)*c_stawka_n)/E40 -> 400 | F41: =(c_stawka_1+IF(F40>=2,c_stawka_2,0)+MAX(0,F40-2)*c_stawka_n)/F40 -> 400 | G41: =(c_stawka_1+IF(G40>=2,c_stawka_2,0)+MAX(0,G40-2)*c_stawka_n)/G40 -> 400 | I41: =(c_stawka_1+IF(I40>=2,c_stawka_2,0)+MAX(0,I40-2)*c_stawka_n)/I40 -> 450 | J41: =(c_stawka_1+IF(J40>=2,c_stawka_2,0)+MAX(0,J40-2)*c_stawka_n)/J40 -> 416.66667 | K41: =(c_stawka_1+IF(K40>=2,c_stawka_2,0)+MAX(0,K40-2)*c_stawka_n)/K40 -> 400 | L41: =(c_stawka_1+IF(L40>=2,c_stawka_2,0)+MAX(0,L40-2)*c_stawka_n)/L40 -> 390 | M41: =(c_stawka_1+IF(M40>=2,c_stawka_2,0)+MAX(0,M40-2)*c_stawka_n)/M40 -> 383.33333 | N41: =(c_stawka_1+IF(N40>=2,c_stawka_2,0)+MAX(0,N40-2)*c_stawka_n)/N40 -> 378.57143
B42: Osobodni montażu (dawne F50) | D42: =c_osd_S*in_S+c_osd_D*in_D+c_osd_NP*in_NP+m_utr+D39*c_slupek_rbd*m_MP -> 0 | E42: =c_osd_S*in_S+c_osd_D*in_D+c_osd_NP*in_NP+m_utr+E39*c_slupek_rbd*m_MP -> 0 | F42: =c_osd_S*in_S+c_osd_D*in_D+c_osd_NP*in_NP+m_utr+F39*c_slupek_rbd*m_MP -> 0 | G42: =c_osd_S*in_S+c_osd_D*in_D+c_osd_NP*in_NP+m_utr+G39*c_slupek_rbd*m_MP -> 0 | I42: =c_osd_S*in_S+c_osd_D*in_D+c_osd_NP*in_NP+m_utr+I39*c_slupek_rbd*m_MP -> 0 | J42: =c_osd_S*in_S+c_osd_D*in_D+c_osd_NP*in_NP+m_utr+J39*c_slupek_rbd*m_MP -> 0 | K42: =c_osd_S*in_S+c_osd_D*in_D+c_osd_NP*in_NP+m_utr+K39*c_slupek_rbd*m_MP -> 0 | L42: =c_osd_S*in_S+c_osd_D*in_D+c_osd_NP*in_NP+m_utr+L39*c_slupek_rbd*m_MP -> 0 | M42: =c_osd_S*in_S+c_osd_D*in_D+c_osd_NP*in_NP+m_utr+M39*c_slupek_rbd*m_MP -> 0 | N42: =c_osd_S*in_S+c_osd_D*in_D+c_osd_NP*in_NP+m_utr+N39*c_slupek_rbd*m_MP -> 0
B43: Iteracja 1: tygodnie / dni montażu | D43: =IF(e_krk,CEILING((D42+(e_podr_pom+D40*(e_rozl_dni+IF(in_wzor="Uproszczony",2*e_km_mon/c_km_dzien*1,(1+0.1*MAX(0,800-e_km_mon)/100)*e_km_mon*1/500))))/D40,1),CEILING(CEILING((D42+(e_podr_pom+D40*(e_rozl_dni+IF(in_wzor="Uproszczony",2*e_km_mon/c_km_dzien*1,(1+0.1*MAX(0,800-e_km_mon)/100)*e_km_mon*1/500))))/D40,1)/c_dni_tydzien,1)) -> 1 | E43: =IF(e_krk,CEILING((E42+(e_podr_pom+E40*(e_rozl_dni+IF(in_wzor="Uproszczony",2*e_km_mon/c_km_dzien*1,(1+0.1*MAX(0,800-e_km_mon)/100)*e_km_mon*1/500))))/E40,1),CEILING(CEILING((E42+(e_podr_pom+E40*(e_rozl_dni+IF(in_wzor="Uproszczony",2*e_km_mon/c_km_dzien*1,(1+0.1*MAX(0,800-e_km_mon)/100)*e_km_mon*1/500))))/E40,1)/c_dni_tydzien,1)) -> 1 | F43: =IF(e_krk,CEILING((F42+(e_podr_pom+F40*(e_rozl_dni+IF(in_wzor="Uproszczony",2*e_km_mon/c_km_dzien*1,(1+0.1*MAX(0,800-e_km_mon)/100)*e_km_mon*1/500))))/F40,1),CEILING(CEILING((F42+(e_podr_pom+F40*(e_rozl_dni+IF(in_wzor="Uproszczony",2*e_km_mon/c_km_dzien*1,(1+0.1*MAX(0,800-e_km_mon)/100)*e_km_mon*1/500))))/F40,1)/c_dni_tydzien,1)) -> 1 | G43: =IF(e_krk,CEILING((G42+(e_podr_pom+G40*(e_rozl_dni+IF(in_wzor="Uproszczony",2*e_km_mon/c_km_dzien*1,(1+0.1*MAX(0,800-e_km_mon)/100)*e_km_mon*1/500))))/G40,1),CEILING(CEILING((G42+(e_podr_pom+G40*(e_rozl_dni+IF(in_wzor="Uproszczony",2*e_km_mon/c_km_dzien*1,(1+0.1*MAX(0,800-e_km_mon)/100)*e_km_mon*1/500))))/G40,1)/c_dni_tydzien,1)) -> 1 | I43: =IF(e_krk,CEILING((I42+(e_podr_pom+I40*(e_rozl_dni+IF(in_wzor="Uproszczony",2*e_km_mon/c_km_dzien*1,(1+0.1*MAX(0,800-e_km_mon)/100)*e_km_mon*1/500))))/I40,1),CEILING(CEILING((I42+(e_podr_pom+I40*(e_rozl_dni+IF(in_wzor="Uproszczony",2*e_km_mon/c_km_dzien*1,(1+0.1*MAX(0,800-e_km_mon)/100)*e_km_mon*1/500))))/I40,1)/c_dni_tydzien,1)) -> 1 | J43: =IF(e_krk,CEILING((J42+(e_podr_pom+J40*(e_rozl_dni+IF(in_wzor="Uproszczony",2*e_km_mon/c_km_dzien*1,(1+0.1*MAX(0,800-e_km_mon)/100)*e_km_mon*1/500))))/J40,1),CEILING(CEILING((J42+(e_podr_pom+J40*(e_rozl_dni+IF(in_wzor="Uproszczony",2*e_km_mon/c_km_dzien*1,(1+0.1*MAX(0,800-e_km_mon)/100)*e_km_mon*1/500))))/J40,1)/c_dni_tydzien,1)) -> 1 | K43: =IF(e_krk,CEILING((K42+(e_podr_pom+K40*(e_rozl_dni+IF(in_wzor="Uproszczony",2*e_km_mon/c_km_dzien*1,(1+0.1*MAX(0,800-e_km_mon)/100)*e_km_mon*1/500))))/K40,1),CEILING(CEILING((K42+(e_podr_pom+K40*(e_rozl_dni+IF(in_wzor="Uproszczony",2*e_km_mon/c_km_dzien*1,(1+0.1*MAX(0,800-e_km_mon)/100)*e_km_mon*1/500))))/K40,1)/c_dni_tydzien,1)) -> 1 | L43: =IF(e_krk,CEILING((L42+(e_podr_pom+L40*(e_rozl_dni+IF(in_wzor="Uproszczony",2*e_km_mon/c_km_dzien*1,(1+0.1*MAX(0,800-e_km_mon)/100)*e_km_mon*1/500))))/L40,1),CEILING(CEILING((L42+(e_podr_pom+L40*(e_rozl_dni+IF(in_wzor="Uproszczony",2*e_km_mon/c_km_dzien*1,(1+0.1*MAX(0,800-e_km_mon)/100)*e_km_mon*1/500))))/L40,1)/c_dni_tydzien,1)) -> 1 | M43: =IF(e_krk,CEILING((M42+(e_podr_pom+M40*(e_rozl_dni+IF(in_wzor="Uproszczony",2*e_km_mon/c_km_dzien*1,(1+0.1*MAX(0,800-e_km_mon)/100)*e_km_mon*1/500))))/M40,1),CEILING(CEILING((M42+(e_podr_pom+M40*(e_rozl_dni+IF(in_wzor="Uproszczony",2*e_km_mon/c_km_dzien*1,(1+0.1*MAX(0,800-e_km_mon)/100)*e_km_mon*1/500))))/M40,1)/c_dni_tydzien,1)) -> 1 | N43: =IF(e_krk,CEILING((N42+(e_podr_pom+N40*(e_rozl_dni+IF(in_wzor="Uproszczony",2*e_km_mon/c_km_dzien*1,(1+0.1*MAX(0,800-e_km_mon)/100)*e_km_mon*1/500))))/N40,1),CEILING(CEILING((N42+(e_podr_pom+N40*(e_rozl_dni+IF(in_wzor="Uproszczony",2*e_km_mon/c_km_dzien*1,(1+0.1*MAX(0,800-e_km_mon)/100)*e_km_mon*1/500))))/N40,1)/c_dni_tydzien,1)) -> 1
B44: Iteracja 2: tygodnie / dni montażu | D44: =IF(e_krk,CEILING((D42+(e_podr_pom+D40*(e_rozl_dni+IF(in_wzor="Uproszczony",2*e_km_mon/c_km_dzien*D43,(1+0.1*MAX(0,800-e_km_mon)/100)*e_km_mon*D43/500))))/D40,1),CEILING(CEILING((D42+(e_podr_pom+D40*(e_rozl_dni+IF(in_wzor="Uproszczony",2*e_km_mon/c_km_dzien*D43,(1+0.1*MAX(0,800-e_km_mon)/100)*e_km_mon*D43/500))))/D40,1)/c_dni_tydzien,1)) -> 1 | E44: =IF(e_krk,CEILING((E42+(e_podr_pom+E40*(e_rozl_dni+IF(in_wzor="Uproszczony",2*e_km_mon/c_km_dzien*E43,(1+0.1*MAX(0,800-e_km_mon)/100)*e_km_mon*E43/500))))/E40,1),CEILING(CEILING((E42+(e_podr_pom+E40*(e_rozl_dni+IF(in_wzor="Uproszczony",2*e_km_mon/c_km_dzien*E43,(1+0.1*MAX(0,800-e_km_mon)/100)*e_km_mon*E43/500))))/E40,1)/c_dni_tydzien,1)) -> 1 | F44: =IF(e_krk,CEILING((F42+(e_podr_pom+F40*(e_rozl_dni+IF(in_wzor="Uproszczony",2*e_km_mon/c_km_dzien*F43,(1+0.1*MAX(0,800-e_km_mon)/100)*e_km_mon*F43/500))))/F40,1),CEILING(CEILING((F42+(e_podr_pom+F40*(e_rozl_dni+IF(in_wzor="Uproszczony",2*e_km_mon/c_km_dzien*F43,(1+0.1*MAX(0,800-e_km_mon)/100)*e_km_mon*F43/500))))/F40,1)/c_dni_tydzien,1)) -> 1 | G44: =IF(e_krk,CEILING((G42+(e_podr_pom+G40*(e_rozl_dni+IF(in_wzor="Uproszczony",2*e_km_mon/c_km_dzien*G43,(1+0.1*MAX(0,800-e_km_mon)/100)*e_km_mon*G43/500))))/G40,1),CEILING(CEILING((G42+(e_podr_pom+G40*(e_rozl_dni+IF(in_wzor="Uproszczony",2*e_km_mon/c_km_dzien*G43,(1+0.1*MAX(0,800-e_km_mon)/100)*e_km_mon*G43/500))))/G40,1)/c_dni_tydzien,1)) -> 1 | I44: =IF(e_krk,CEILING((I42+(e_podr_pom+I40*(e_rozl_dni+IF(in_wzor="Uproszczony",2*e_km_mon/c_km_dzien*I43,(1+0.1*MAX(0,800-e_km_mon)/100)*e_km_mon*I43/500))))/I40,1),CEILING(CEILING((I42+(e_podr_pom+I40*(e_rozl_dni+IF(in_wzor="Uproszczony",2*e_km_mon/c_km_dzien*I43,(1+0.1*MAX(0,800-e_km_mon)/100)*e_km_mon*I43/500))))/I40,1)/c_dni_tydzien,1)) -> 1 | J44: =IF(e_krk,CEILING((J42+(e_podr_pom+J40*(e_rozl_dni+IF(in_wzor="Uproszczony",2*e_km_mon/c_km_dzien*J43,(1+0.1*MAX(0,800-e_km_mon)/100)*e_km_mon*J43/500))))/J40,1),CEILING(CEILING((J42+(e_podr_pom+J40*(e_rozl_dni+IF(in_wzor="Uproszczony",2*e_km_mon/c_km_dzien*J43,(1+0.1*MAX(0,800-e_km_mon)/100)*e_km_mon*J43/500))))/J40,1)/c_dni_tydzien,1)) -> 1 | K44: =IF(e_krk,CEILING((K42+(e_podr_pom+K40*(e_rozl_dni+IF(in_wzor="Uproszczony",2*e_km_mon/c_km_dzien*K43,(1+0.1*MAX(0,800-e_km_mon)/100)*e_km_mon*K43/500))))/K40,1),CEILING(CEILING((K42+(e_podr_pom+K40*(e_rozl_dni+IF(in_wzor="Uproszczony",2*e_km_mon/c_km_dzien*K43,(1+0.1*MAX(0,800-e_km_mon)/100)*e_km_mon*K43/500))))/K40,1)/c_dni_tydzien,1)) -> 1 | L44: =IF(e_krk,CEILING((L42+(e_podr_pom+L40*(e_rozl_dni+IF(in_wzor="Uproszczony",2*e_km_mon/c_km_dzien*L43,(1+0.1*MAX(0,800-e_km_mon)/100)*e_km_mon*L43/500))))/L40,1),CEILING(CEILING((L42+(e_podr_pom+L40*(e_rozl_dni+IF(in_wzor="Uproszczony",2*e_km_mon/c_km_dzien*L43,(1+0.1*MAX(0,800-e_km_mon)/100)*e_km_mon*L43/500))))/L40,1)/c_dni_tydzien,1)) -> 1 | M44: =IF(e_krk,CEILING((M42+(e_podr_pom+M40*(e_rozl_dni+IF(in_wzor="Uproszczony",2*e_km_mon/c_km_dzien*M43,(1+0.1*MAX(0,800-e_km_mon)/100)*e_km_mon*M43/500))))/M40,1),CEILING(CEILING((M42+(e_podr_pom+M40*(e_rozl_dni+IF(in_wzor="Uproszczony",2*e_km_mon/c_km_dzien*M43,(1+0.1*MAX(0,800-e_km_mon)/100)*e_km_mon*M43/500))))/M40,1)/c_dni_tydzien,1)) -> 1 | N44: =IF(e_krk,CEILING((N42+(e_podr_pom+N40*(e_rozl_dni+IF(in_wzor="Uproszczony",2*e_km_mon/c_km_dzien*N43,(1+0.1*MAX(0,800-e_km_mon)/100)*e_km_mon*N43/500))))/N40,1),CEILING(CEILING((N42+(e_podr_pom+N40*(e_rozl_dni+IF(in_wzor="Uproszczony",2*e_km_mon/c_km_dzien*N43,(1+0.1*MAX(0,800-e_km_mon)/100)*e_km_mon*N43/500))))/N40,1)/c_dni_tydzien,1)) -> 1
...
