Workbook

Sheet Dane
B2: KALKULATOR NK38 - DANE WEJŚCIOWE
B3: Wypełniasz tylko żółte pola. Puste pole = 0. Wynik: arkusz Podsumowanie.
B5: 1. Inwestycja
B6: Nazwa / adres inwestycji | C6: ul. Kasprowicza 18 Warszawa
B7: Data oferty
B8: Nr oferty / handlowiec | C8: 20261014-SNK
B9: Opis / wariant (H, L, P, Hpoj ...)
B11: 2. Lokalizacja
B12: Lokalizacja | C12: Poza Krakowem | E12: Kraków: montaż liczony w dniach, bez hotelu i diet
B13: Odległość montażu od Krakowa [km, w jedną stronę] | C13: 330
B14: Odległość pomiary / odbiory [km] (puste = jak wyżej) | C14: 280 | E14: W pliku WAW: pomiary 280 km, montaż 330 km
B16: 3. Urządzenia
B17: Typ urządzenia | C17: NK38
B18: Platformy pojedyncze S (2 MP) | C18: 0
B19: Platformy podwójne D (4 MP) | C19: 15
B20: Systemy dla N.P. (2 MP) | C20: 0
B21: Agregaty | C21: 3 | E21: 1 agregat do 6 platform
B22: Magistrala EXTRA [odcinki 6 m] | C22: 4
B23: Barierki [szt. na stronę] | C23: 30
B24: Maskownice / bariery tylne | C24: 5
B26: 4. Wymiary niestandardowe (ile platform danego typu)
C27: S | D27: D | E27: Pozostałe platformy = wymiar standardowy
B28: Zagłębienie 175 cm | C28: 0 | D28: 0
B29: Zagłębienie 180 cm | C29: 0 | D29: 0
B30: Zagłębienie 185 cm | C30: 0 | D30: 0
B31: Zagłębienie 190 cm | C31: 0 | D31: 0
B32: Zagłębienie 195 cm | C32: 0 | D32: 0
B33: Zagłębienie 200 cm | C33: 0 | D33: 15
B34: Zagłębienie 210 cm | C34: 0 | D34: 0
B35: Zagłębienie 220 cm | C35: 0 | D35: 0
B36: Zagłębienie 225 cm | C36: 0 | D36: 0
B37: Zagłębienie 170 cm (standard) - wyliczone | C37: =in_S-SUM(in_gl_S) -> 0 | D37: =in_D-SUM(in_gl_D) -> 0
B38: Szerokość 260 (S) / 520 (D) | C38: 0 | D38: 0
B39: Szerokość 270 (S) / 540 (D) | C39: 0 | D39: 0
B40: Długość zagłębienia 500-510 cm | C40: 0 | D40: 0
B41: Długość zagłębienia 540 cm | C41: 0 | D41: 0
B42: Długość zagłębienia 550 cm | C42: 0 | D42: 0
B44: 5. Transport i ekipa
B45: Liczba transportów (TIR) | C45: 3
B46: Cena transportu / TIR | C46: 4000 | E46: Podpowiedź w Cenniku: KRK 1600, WAW/WRO 3300, POZ/ZG 4500
...

Sheet Podsumowanie
B2: PODSUMOWANIE OFERTY NK38
B3: =in_nazwa&" | "&IF(ISBLANK(in_data),"",TEXT(in_data,"yyyy-mm-dd"))&" | "&in_nr -> ul. Kasprowicza 18 Warszawa | | 20261014-SNK
B4: =in_typ&" "&IF(in_S>0,in_S&"xS ","")&IF(in_D>0,in_D&"xD ","")&IF(in_NP>0,in_NP&"xNP ","")&in_agregaty&"xA | "&m_MP&" MP | "&in_lok -> NK38 15xD 3xA | 60 MP | Poza Krakowem
B6: Wariant | C6: 2000 kg | D6: 2500 kg | E6: 2000 kg + słupki | F6: 2500 kg + słupki
B7: CENA KONTRAKTU NETTO | C7: =Obliczenia!D67 -> 951980.82 | D7: =Obliczenia!E67 -> 999035.72 | E7: =Obliczenia!F67 -> 1095544.9 | F7: =Obliczenia!G67 -> 1142599.8
B8: Cena za miejsce postojowe | C8: =Obliczenia!D69 -> 15866.347 | D8: =Obliczenia!E69 -> 16650.595 | E8: =Obliczenia!F69 -> 18259.082 | F8: =Obliczenia!G69 -> 19043.33
B9: Cena za MP [EUR] | C9: =Obliczenia!D70 -> 3668.5195 | D9: =Obliczenia!E70 -> 3849.8486 | E9: =Obliczenia!F70 -> 4221.753 | F9: =Obliczenia!G70 -> 4403.0821
B10: Cena minimalna (zysk min., dźwig 2000) | C10: =Obliczenia!D73 -> 920388.54 | D10: =Obliczenia!E73 -> 965934.62 | E10: =Obliczenia!F73 -> 1059401.3 | F10: =Obliczenia!G73 -> 1104947.4
B11: Zysk | C11: =Obliczenia!D65 -> 115264.99 | D11: =Obliczenia!E65 -> 121025.88 | E11: =Obliczenia!F65 -> 132642.47 | F11: =Obliczenia!G65 -> 138403.36
B12: Koszt rzeczywisty | C12: =Obliczenia!D68 -> 836715.83 | D12: =Obliczenia!E68 -> 878009.84 | E12: =Obliczenia!F68 -> 962902.43 | F12: =Obliczenia!G68 -> 1004196.4
B14: Urządzenia (materiały) | C14: =Obliczenia!D49 -> 649059.6 | D14: =Obliczenia!E49 -> 688003.18 | E14: =Obliczenia!F49 -> 649059.6 | F14: =Obliczenia!G49 -> 688003.18
B15: Słupki e-ładowarek | C15: =Obliczenia!D50 -> 0 | D15: =Obliczenia!E50 -> 0 | E15: =Obliczenia!F50 -> 102000 | F15: =Obliczenia!G50 -> 102000
B16: Transport, dźwig, rozładunek | C16: =Obliczenia!D53+Obliczenia!D55+Obliczenia!D56 -> 24300 | D16: =Obliczenia!E53+Obliczenia!E55+Obliczenia!E56 -> 24300 | E16: =Obliczenia!F53+Obliczenia!F55+Obliczenia!F56 -> 24300 | F16: =Obliczenia!G53+Obliczenia!G55+Obliczenia!G56 -> 24300
B17: Robocizna (montaż, rozładunek, dojazdy) | C17: =Obliczenia!D59+Obliczenia!D57+Obliczenia!D58 -> 67392.32 | D17: =Obliczenia!E59+Obliczenia!E57+Obliczenia!E58 -> 67392.32 | E17: =Obliczenia!F59+Obliczenia!F57+Obliczenia!F58 -> 77824.64 | F17: =Obliczenia!G59+Obliczenia!G57+Obliczenia!G58 -> 77824.64
B18: Hotel, diety, paliwo | C18: =Obliczenia!D52+Obliczenia!D60+Obliczenia!D51 -> 38439.436 | D18: =Obliczenia!E52+Obliczenia!E60+Obliczenia!E51 -> 38439.436 | E18: =Obliczenia!F52+Obliczenia!F60+Obliczenia!F51 -> 43478.872 | F18: =Obliczenia!G52+Obliczenia!G60+Obliczenia!G51 -> 43478.872
B19: KOB + GDW + podatek | C19: =Obliczenia!D63+Obliczenia!D64+Obliczenia!D66 -> 57524.471 | D19: =Obliczenia!E63+Obliczenia!E64+Obliczenia!E66 -> 59874.912 | E19: =Obliczenia!F63+Obliczenia!F64+Obliczenia!F66 -> 66239.316 | F19: =Obliczenia!G63+Obliczenia!G64+Obliczenia!G66 -> 68589.757
B21: Dni pracy ekipy | C21: =Obliczenia!D47 -> 43 | D21: =Obliczenia!E47 -> 43 | E21: =Obliczenia!F47 -> 49 | F21: =Obliczenia!G47 -> 49
B22: Tygodnie / dni montażu (wyjazdy) | C22: =Obliczenia!D44 -> 9 | D22: =Obliczenia!E44 -> 9 | E22: =Obliczenia!F44 -> 10 | F22: =Obliczenia!G44 -> 10
B23: Osobodni razem | C23: =Obliczenia!D46 -> 168.4808 | D23: =Obliczenia!E46 -> 168.4808 | E23: =Obliczenia!F46 -> 194.5616 | F23: =Obliczenia!G46 -> 194.5616
B25: Informacyjnie (poza ceną)
B26: Malowanie proszkowe RAL | C26: =m_malowanie -> 208500
B27: Słupki 22 kW zamiast 3,7 kW (cena słupków) | C27: =m_slupki22 -> 378000
B28: Konserwacja roczna (40 / 45 / 50 zł/MP/mies.) | C28: =TEXT(c_konserw*m_MP*12,"#,##0")&" / "&TEXT(c_konserw2*m_MP*12,"#,##0")&" / "&TEXT(c_konserw3*m_MP*12,"#,##0")&" zł" -> 28,800 / 32,400 / 36,000 zł
B29: Przegląd półroczny (40 / 45 / 50 zł/MP/mies. x 6) | C29: =TEXT(c_konserw*m_MP*6,"#,##0")&" / "&TEXT(c_konserw2*m_MP*6,"#,##0")&" / "&TEXT(c_konserw3*m_MP*6,"#,##0")&" zł" -> 14,400 / 16,200 / 18,000 zł
B31: Kontrola danych: | C31: =IF(COUNTIF(Dane!B66:B71,"ok")=6,"wszystko ok","sprawdź arkusz Dane") -> wszystko ok

Sheet Cennik
B2: CENNIK I STAŁE KALKULACYJNE NK38
B3: Zmiana ceny tutaj działa we wszystkich formułach. Kolumna E = skąd wartość pochodzi w starym arkuszu.
B5: Platformy
B6: Platforma podwójna NK38-500-170-530 (4 MP) | C6: 32500 | E6: NK38!E32
B7: Dopłata za NK37 / system | C7: 700 | E7: NK38!F1
B8: Cena S jako ułamek ceny D | C8: 0.61 | E8: NK38!F3
B9: Cena systemu N.P. jako ułamek ceny D | C9: 0.85 | E9: NK38!E27
B10: Szerokość S 260 cm | C10: 1170 | E10: NK38!E8
B11: Szerokość S 270 cm | C11: 1560 | E11: NK38!E9
B12: Szerokość D 520 cm | C12: 1820 | E12: NK38!E34
B13: Szerokość D 540 cm | C13: 3110 | E13: NK38!E35
B14: Długość zagłębienia 500-510 cm | C14: 2340 | E14: NK38!E21/E47
B15: Dopłata za 1 cm długości (ułamek ceny platformy) | C15: 0.00127 | E15: NK38!E22 (4 kg/cm z 3150 kg)
B16: Dopłata Q=2500 kg (domyślnie, nadpisz w Dane) | C16: 0.06 | E16: NK38!D90
B17: Hydraulika
B18: Agregat 11,5 l/min (do 6 platform) | C18: 6500 | E18: NK38!E56
B19: Olej 150 l / agregat | C19: 1500 | E19: NK38!D134
B20: Elementy drobne / agregat | C20: 200 | E20: NK38!D135
B21: Transport agregatu | C21: 500 | E21: NK38!F57
B22: Transport siłowników / platformę | C22: 50 | E22: NK38!F57
B23: Siłownik standard (zagł. 170) | C23: 1080 | E23: NK38!D130
B24: Siłownik do zagł. 2000 | C24: 1175 | E24: NK38!D129
B25: Siłownik do zagł. 2250 | C25: 1250 | E25: NK38!D128
B26: Magistrala EXTRA / 6 m | C26: =0.2*11+0.4*11+2*14+6*11+6*5+6*10 -> 190.6 | E26: NK38!D133
B27: Barierki, elektryka, administracja
B28: Barierka na stronę (Metazet 538 zł) | C28: 600 | E28: NK38!E66
B29: Maskownica / bariera tylna (Metazet 608 zł) | C29: 700 | E29: NK38!E67
B30: Elektryka - skrzynka zasilająca / agregat | C30: 1000 | E30: NK38!D121
B31: Administracja, koszty biura / agregat | C31: 1800 | E31: NK38!D125
B32: Opcje (poza ceną standard)
B33: Malowanie proszkowe RAL - system S | C33: 6400 | E33: NK38!E92
B34: Malowanie proszkowe RAL - system D / NP | C34: 13500 | E34: NK38!E93
B35: Malowanie barierki na stronę | C35: 200 | E35: NK38!E94
B36: Słupek e-ładowarki do 3,7 kW / MP | C36: 1700 | E36: NK38!E97, KAL!O55
B37: Słupek e-ładowarki do 22 kW / MP | C37: 6300 | E37: NK38!E98
B38: Robocizna słupka (roboczodni / MP) | C38: 0.37 | E38: KAL!B49
B39: Montaż - pracochłonność
B40: Osobodni montażu / system S | C40: 5.5 | E40: KAL!F16
B41: Osobodni montażu / system D | C41: 7 | E41: KAL!F16
B42: Osobodni montażu / system NP | C42: 7 | E42: KAL!F17
...

Sheet Obliczenia
B2: OBLICZENIA (nie edytować)
B4: A. Materiały i urządzenia (dawny arkusz 'NK38 ...')
B5: Cena platformy D | C5: =c_cena_D+IF(in_typ="NK37",c_doplata_NK37,0) -> 32500
B6: Cena platformy S | C6: =c_wsp_S*m_cena_D -> 19825
B7: Cena systemu N.P. | C7: =c_wsp_NP*m_cena_D -> 27625
B8: Platformy S + N.P. (do składowych) | C8: =in_S+in_NP -> 0
B9: Razem platform | C9: =in_S+in_D+in_NP -> 15
B10: Miejsca postojowe | C10: =2*in_S+2*in_NP+4*in_D -> 60
B11: Platformy S z dopłatami | C11: =m_cena_S*in_S+c_szer_260*in_szer1_S+c_szer_270*in_szer2_S+SUMPRODUCT(in_gl_S,t_gl_doplata)+c_dl_500*in_dl500_S+CEILING(m_cena_S*c_dl_wsp*10,100)*in_dl540_S+CEILING(m_cena_S*c_dl_wsp*20,100)*in_dl550_S -> 0
B12: Platformy D z dopłatami | C12: =m_cena_D*in_D+c_szer_520*in_szer1_D+c_szer_540*in_szer2_D+SUMPRODUCT(in_gl_D,t_gl_doplata)+c_dl_500*in_dl500_D+m_cena_D*c_dl_wsp*10*in_dl540_D+m_cena_D*c_dl_wsp*20*in_dl550_D -> 498000
B13: Platformy N.P. | C13: =m_cena_NP*in_NP -> 0
B14: Siłowniki 2000 [szt. par] | C14: =SUMPRODUCT((t_gl_silownik=2000)*(in_gl_S+in_gl_D)) -> 15
B15: Siłowniki 2250 [szt. par] | C15: =SUMPRODUCT((t_gl_silownik=2250)*(in_gl_S+in_gl_D)) -> 0
B16: Siłowniki standard [szt. par] (N.P. pominięte jak w starym) | C16: =in_S+in_D-m_sil_2000-m_sil_2250 -> 0
B17: Hydraulika | C17: =in_agregaty*(c_agregat+c_hydr_drobne+c_olej+c_transp_agregatu)+m_platformy*c_transp_silownikow+2*(c_sil_1700*m_sil_std+c_sil_2000*m_sil_2000+c_sil_2250*m_sil_2250)+in_magistrala*c_magistrala+SUMPRODUCT((t_sk_grupa="Hydraulika")*t_sk_cena*(t_sk_S*m_SN+t_sk_D*in_D)) -> 69567.4
B18: Barierki i maskownice | C18: =in_barierki*c_barierka+in_maskownice*c_maskownica -> 21500
B19: Elektryka | C19: =in_agregaty*c_skrzynka_zasil+SUMPRODUCT((t_sk_grupa="Elektryka")*t_sk_cena*(t_sk_S*m_SN+t_sk_D*in_D)) -> 8580
B20: Mechanika zakupowa i pozostałe | C20: =in_agregaty*c_admin+SUMPRODUCT((t_sk_grupa="Mechanika")*t_sk_cena*(t_sk_S*m_SN+t_sk_D*in_D)) -> 51412.2
B21: SUMA STANDARD Q=2000 (dawne F87) | C21: =m_plat_S+m_plat_D+m_plat_NP+m_hydraulika+m_barierki+m_elektryka+m_mechanika -> 649059.6
B22: SUMA Q=2500 (dawne F90) | C22: =m_suma_2000*(1+in_q2500) -> 688003.18
B23: Opcja: malowanie proszkowe RAL (poza sumą) | C23: =c_mal_S*in_S+c_mal_D*(in_D+in_NP)+c_mal_bar*in_barierki -> 208500
B24: Opcja: słupki 22 kW (poza sumą) | C24: =c_slupek22*m_MP -> 378000
B25: "Tonaż" - dodatkowe osobodni (magistrala, barierki) | C25: =ROUNDUP(in_magistrala*c_osd_magistrala+(in_barierki+in_maskownice)*c_osd_barierka,0) -> 20
B27: Odległość pomiary/odbiory [km] | C27: =IF(ISBLANK(in_km_pom),in_km,in_km_pom) -> 280
B28: Osoby na montażu | C28: =MAX(1,COUNTIF(in_stawki,">0")) -> 4
B29: Średnia stawka dzienna | C29: =SUM(in_stawki)/e_osoby -> 400
B30: Dni rozładunku | C30: =IF(ISBLANK(in_rozl_dni),c_rozl_TIR*in_tir,in_rozl_dni) -> 1.5
B31: Kraków? | C31: =in_lok="Kraków" -> FALSE
B32: Czas podróży pomiary + odbiory [osobodni] | C32: =(c_pomiary_osoby+c_odbiory_osoby)*IF(C_kmpom<800,(1+0.1*(800-C_kmpom)/100)*C_kmpom*1/500,C_kmpom/800) -> 2.5536
B34: B. Montaż (dawny arkusz '<Inwestycja>-NK38') - warianty w kolumnach
B35: Wariant | D35: 2000 kg | E35: 2500 kg | F35: 2000 kg + słupki | G35: 2500 kg + słupki
B36: Q=2500? (1/0) | D36: 0 | E36: 1 | F36: 0 | G36: 1
B37: Słupki e-ładowarek? (1/0) | D37: 0 | E37: 0 | F37: 1 | G37: 1
B38: Osobodni montażu (dawne F50) | D38: =c_osd_S*in_S+c_osd_D*in_D+c_osd_NP*in_NP+m_tonaz+D37*c_slupek_rbd*m_MP -> 125 | E38: =c_osd_S*in_S+c_osd_D*in_D+c_osd_NP*in_NP+m_tonaz+E37*c_slupek_rbd*m_MP -> 125 | F38: =c_osd_S*in_S+c_osd_D*in_D+c_osd_NP*in_NP+m_tonaz+F37*c_slupek_rbd*m_MP -> 147.2 | G38: =c_osd_S*in_S+c_osd_D*in_D+c_osd_NP*in_NP+m_tonaz+G37*c_slupek_rbd*m_MP -> 147.2
B39: Iteracja 1: tygodnie / dni montażu | D39: =IF(e_krk,CEILING((D38+(e_podr_pom+e_osoby*(e_rozl_dni+IF(in_km<800,(1+0.1*(800-in_km)/100)*in_km*1/500,in_km/800))))/e_osoby,1),CEILING(CEILING((D38+(e_podr_pom+e_osoby*(e_rozl_dni+IF(in_km<800,(1+0.1*(800-in_km)/100)*in_km*1/500,in_km/800))))/e_osoby,1)/c_dni_tydzien,1)) -> 7 | E39: =IF(e_krk,CEILING((E38+(e_podr_pom+e_osoby*(e_rozl_dni+IF(in_km<800,(1+0.1*(800-in_km)/100)*in_km*1/500,in_km/800))))/e_osoby,1),CEILING(CEILING((E38+(e_podr_pom+e_osoby*(e_rozl_dni+IF(in_km<800,(1+0.1*(800-in_km)/100)*in_km*1/500,in_km/800))))/e_osoby,1)/c_dni_tydzien,1)) -> 7 | F39: =IF(e_krk,CEILING((F38+(e_podr_pom+e_osoby*(e_rozl_dni+IF(in_km<800,(1+0.1*(800-in_km)/100)*in_km*1/500,in_km/800))))/e_osoby,1),CEILING(CEILING((F38+(e_podr_pom+e_osoby*(e_rozl_dni+IF(in_km<800,(1+0.1*(800-in_km)/100)*in_km*1/500,in_km/800))))/e_osoby,1)/c_dni_tydzien,1)) -> 8 | G39: =IF(e_krk,CEILING((G38+(e_podr_pom+e_osoby*(e_rozl_dni+IF(in_km<800,(1+0.1*(800-in_km)/100)*in_km*1/500,in_km/800))))/e_osoby,1),CEILING(CEILING((G38+(e_podr_pom+e_osoby*(e_rozl_dni+IF(in_km<800,(1+0.1*(800-in_km)/100)*in_km*1/500,in_km/800))))/e_osoby,1)/c_dni_tydzien,1)) -> 8
B40: Iteracja 2: tygodnie / dni montażu | D40: =IF(e_krk,CEILING((D38+(e_podr_pom+e_osoby*(e_rozl_dni+IF(in_km<800,(1+0.1*(800-in_km)/100)*in_km*D39/500,in_km/800))))/e_osoby,1),CEILING(CEILING((D38+(e_podr_pom+e_osoby*(e_rozl_dni+IF(in_km<800,(1+0.1*(800-in_km)/100)*in_km*D39/500,in_km/800))))/e_osoby,1)/c_dni_tydzien,1)) -> 9 | E40: =IF(e_krk,CEILING((E38+(e_podr_pom+e_osoby*(e_rozl_dni+IF(in_km<800,(1+0.1*(800-in_km)/100)*in_km*E39/500,in_km/800))))/e_osoby,1),CEILING(CEILING((E38+(e_podr_pom+e_osoby*(e_rozl_dni+IF(in_km<800,(1+0.1*(800-in_km)/100)*in_km*E39/500,in_km/800))))/e_osoby,1)/c_dni_tydzien,1)) -> 9 | F40: =IF(e_krk,CEILING((F38+(e_podr_pom+e_osoby*(e_rozl_dni+IF(in_km<800,(1+0.1*(800-in_km)/100)*in_km*F39/500,in_km/800))))/e_osoby,1),CEILING(CEILING((F38+(e_podr_pom+e_osoby*(e_rozl_dni+IF(in_km<800,(1+0.1*(800-in_km)/100)*in_km*F39/500,in_km/800))))/e_osoby,1)/c_dni_tydzien,1)) -> 10 | G40: =IF(e_krk,CEILING((G38+(e_podr_pom+e_osoby*(e_rozl_dni+IF(in_km<800,(1+0.1*(800-in_km)/100)*in_km*G39/500,in_km/800))))/e_osoby,1),CEILING(CEILING((G38+(e_podr_pom+e_osoby*(e_rozl_dni+IF(in_km<800,(1+0.1*(800-in_km)/100)*in_km*G39/500,in_km/800))))/e_osoby,1)/c_dni_tydzien,1)) -> 10
B41: Iteracja 3: tygodnie / dni montażu | D41: =IF(e_krk,CEILING((D38+(e_podr_pom+e_osoby*(e_rozl_dni+IF(in_km<800,(1+0.1*(800-in_km)/100)*in_km*D40/500,in_km/800))))/e_osoby,1),CEILING(CEILING((D38+(e_podr_pom+e_osoby*(e_rozl_dni+IF(in_km<800,(1+0.1*(800-in_km)/100)*in_km*D40/500,in_km/800))))/e_osoby,1)/c_dni_tydzien,1)) -> 9 | E41: =IF(e_krk,CEILING((E38+(e_podr_pom+e_osoby*(e_rozl_dni+IF(in_km<800,(1+0.1*(800-in_km)/100)*in_km*E40/500,in_km/800))))/e_osoby,1),CEILING(CEILING((E38+(e_podr_pom+e_osoby*(e_rozl_dni+IF(in_km<800,(1+0.1*(800-in_km)/100)*in_km*E40/500,in_km/800))))/e_osoby,1)/c_dni_tydzien,1)) -> 9 | F41: =IF(e_krk,CEILING((F38+(e_podr_pom+e_osoby*(e_rozl_dni+IF(in_km<800,(1+0.1*(800-in_km)/100)*in_km*F40/500,in_km/800))))/e_osoby,1),CEILING(CEILING((F38+(e_podr_pom+e_osoby*(e_rozl_dni+IF(in_km<800,(1+0.1*(800-in_km)/100)*in_km*F40/500,in_km/800))))/e_osoby,1)/c_dni_tydzien,1)) -> 10 | G41: =IF(e_krk,CEILING((G38+(e_podr_pom+e_osoby*(e_rozl_dni+IF(in_km<800,(1+0.1*(800-in_km)/100)*in_km*G40/500,in_km/800))))/e_osoby,1),CEILING(CEILING((G38+(e_podr_pom+e_osoby*(e_rozl_dni+IF(in_km<800,(1+0.1*(800-in_km)/100)*in_km*G40/500,in_km/800))))/e_osoby,1)/c_dni_tydzien,1)) -> 10
B42: Iteracja 4: tygodnie / dni montażu | D42: =IF(e_krk,CEILING((D38+(e_podr_pom+e_osoby*(e_rozl_dni+IF(in_km<800,(1+0.1*(800-in_km)/100)*in_km*D41/500,in_km/800))))/e_osoby,1),CEILING(CEILING((D38+(e_podr_pom+e_osoby*(e_rozl_dni+IF(in_km<800,(1+0.1*(800-in_km)/100)*in_km*D41/500,in_km/800))))/e_osoby,1)/c_dni_tydzien,1)) -> 9 | E42: =IF(e_krk,CEILING((E38+(e_podr_pom+e_osoby*(e_rozl_dni+IF(in_km<800,(1+0.1*(800-in_km)/100)*in_km*E41/500,in_km/800))))/e_osoby,1),CEILING(CEILING((E38+(e_podr_pom+e_osoby*(e_rozl_dni+IF(in_km<800,(1+0.1*(800-in_km)/100)*in_km*E41/500,in_km/800))))/e_osoby,1)/c_dni_tydzien,1)) -> 9 | F42: =IF(e_krk,CEILING((F38+(e_podr_pom+e_osoby*(e_rozl_dni+IF(in_km<800,(1+0.1*(800-in_km)/100)*in_km*F41/500,in_km/800))))/e_osoby,1),CEILING(CEILING((F38+(e_podr_pom+e_osoby*(e_rozl_dni+IF(in_km<800,(1+0.1*(800-in_km)/100)*in_km*F41/500,in_km/800))))/e_osoby,1)/c_dni_tydzien,1)) -> 10 | G42: =IF(e_krk,CEILING((G38+(e_podr_pom+e_osoby*(e_rozl_dni+IF(in_km<800,(1+0.1*(800-in_km)/100)*in_km*G41/500,in_km/800))))/e_osoby,1),CEILING(CEILING((G38+(e_podr_pom+e_osoby*(e_rozl_dni+IF(in_km<800,(1+0.1*(800-in_km)/100)*in_km*G41/500,in_km/800))))/e_osoby,1)/c_dni_tydzien,1)) -> 10
B43: Iteracja 5: tygodnie / dni montażu | D43: =IF(e_krk,CEILING((D38+(e_podr_pom+e_osoby*(e_rozl_dni+IF(in_km<800,(1+0.1*(800-in_km)/100)*in_km*D42/500,in_km/800))))/e_osoby,1),CEILING(CEILING((D38+(e_podr_pom+e_osoby*(e_rozl_dni+IF(in_km<800,(1+0.1*(800-in_km)/100)*in_km*D42/500,in_km/800))))/e_osoby,1)/c_dni_tydzien,1)) -> 9 | E43: =IF(e_krk,CEILING((E38+(e_podr_pom+e_osoby*(e_rozl_dni+IF(in_km<800,(1+0.1*(800-in_km)/100)*in_km*E42/500,in_km/800))))/e_osoby,1),CEILING(CEILING((E38+(e_podr_pom+e_osoby*(e_rozl_dni+IF(in_km<800,(1+0.1*(800-in_km)/100)*in_km*E42/500,in_km/800))))/e_osoby,1)/c_dni_tydzien,1)) -> 9 | F43: =IF(e_krk,CEILING((F38+(e_podr_pom+e_osoby*(e_rozl_dni+IF(in_km<800,(1+0.1*(800-in_km)/100)*in_km*F42/500,in_km/800))))/e_osoby,1),CEILING(CEILING((F38+(e_podr_pom+e_osoby*(e_rozl_dni+IF(in_km<800,(1+0.1*(800-in_km)/100)*in_km*F42/500,in_km/800))))/e_osoby,1)/c_dni_tydzien,1)) -> 10 | G43: =IF(e_krk,CEILING((G38+(e_podr_pom+e_osoby*(e_rozl_dni+IF(in_km<800,(1+0.1*(800-in_km)/100)*in_km*G42/500,in_km/800))))/e_osoby,1),CEILING(CEILING((G38+(e_podr_pom+e_osoby*(e_rozl_dni+IF(in_km<800,(1+0.1*(800-in_km)/100)*in_km*G42/500,in_km/800))))/e_osoby,1)/c_dni_tydzien,1)) -> 10
B44: Tygodnie (lub dni w Krakowie) montażu - przyjęte (dawne B55) | D44: =IF(ISBLANK(in_wyjazdy),D43,in_wyjazdy) -> 9 | E44: =IF(ISBLANK(in_wyjazdy),E43,in_wyjazdy) -> 9 | F44: =IF(ISBLANK(in_wyjazdy),F43,in_wyjazdy) -> 10 | G44: =IF(ISBLANK(in_wyjazdy),G43,in_wyjazdy) -> 10
...
